<?xml version="1.0" ?>
<!-- =================================================================================== -->
<!-- |    This document was autogenerated by xacro from urdf/mavric.xacro              | -->
<!-- |    EDITING THIS FILE BY HAND IS NOT RECOMMENDED                                 | -->
<!-- =================================================================================== -->
<robot name="marvin">
  <!-- Base_link -->
  <link name="base_link"/>
  <!-- Footprint -->
  <link name="base_footprint"/>
  <joint name="base_joint" type="fixed">
    <origin rpy="0 0 0" xyz="0 0 -0.111125"/>
    <parent link="base_link"/>
    <child link="base_footprint"/>
  </joint>
  <!-- Odom -->
  <!-- <link name="odom" />  

    <joint name="odom_joint" type="floating">
        <origin xyz="0 0 0" rpy="0 0 0" />
        <parent link="odom" />
        <child link="base_link" />
    </joint> -->
  <!-- Chassis link -->
  <link name="chassis_link">
    <inertial>
      <origin rpy="0 0 0" xyz="-0.1016 0.0 0.04603749999999998"/>
      <mass value="29.9371"/>
      <inertia ixx="1.706089383513333" ixy="0.0" ixz="0.0" iyy="4.111112082866916" iyz="0.0" izz="4.2591877652095835"/>
    </inertial>
    <visual>
      <!-- Chassis Tower -->
      <origin rpy="0 0 0" xyz="0 0 0.3937"/>
      <geometry>
        <box size="0.2032 0.6095999999999999 0.7874"/>
      </geometry>
    </visual>
    <visual>
      <!-- Chassis Payload -->
      <origin rpy="0 0 0" xyz="0.282575 0 0.1016"/>
      <geometry>
        <box size="0.36195 0.6095999999999999 0.2032"/>
      </geometry>
    </visual>
    <visual>
      <!-- Chassis Electrical -->
      <origin rpy="0 0 0" xyz="-0.29527499999999995 0 0.2794"/>
      <geometry>
        <box size="0.38734999999999997 0.6095999999999999 0.5588"/>
      </geometry>
    </visual>
    <visual>
      <!-- Chassis Caster -->
      <origin rpy="0 0 0" xyz="-0.59055                           0                           0.079375"/>
      <geometry>
        <box size="0.2032 0.6095999999999999 0.05715"/>
      </geometry>
    </visual>
    <collision>
      <origin rpy="0 0 0" xyz="-0.11429999999999996                           0                           0.3937"/>
      <geometry>
        <box size="1.1557 0.6095999999999999 0.7874"/>
      </geometry>
    </collision>
  </link>
  <joint name="chassis_joint" type="fixed">
    <origin rpy="0 0 0" xyz="0 0 0"/>
    <parent link="base_link"/>
    <child link="chassis_link"/>
  </joint>
  <!-- Chassis color -->
  <gazebo reference="chassis_link">
    <material>Gazebo/Blue</material>
  </gazebo>
  <!-- Caster link -->
  <link name="caster_link">
    <inertial>
      <origin rpy="0 0 0" xyz="0 0 0"/>
      <mass value="0.1"/>
      <inertia ixx="0.0003161284" ixy="0.0" ixz="0.0" iyy="0.0003161284" iyz="0.0" izz="0.0003161284"/>
    </inertial>
    <visual>
      <geometry>
        <sphere radius="0.08889999999999999"/>
      </geometry>
    </visual>
    <collision>
      <origin rpy=" 0 0 0" xyz="0 0 0"/>
      <geometry>
        <sphere radius="0.08889999999999999"/>
      </geometry>
      <surface>
        <friction>
          <ode>
            <mu>0.0</mu>
            <mu2>0.0</mu2>
          </ode>
        </friction>
      </surface>
    </collision>
  </link>
  <joint name="caster_joint" type="fixed">
    <origin rpy="0 0 0" xyz="-0.625475 0 -0.02222500000000001"/>
    <parent link="base_link"/>
    <child link="caster_link"/>
  </joint>
  <!-- Caster color -->
  <gazebo reference="caster_link">
    <material>Gazebo/Green</material>
  </gazebo>
  <!-- Wheel link -->
  <link name="right_wheel_link">
    <inertial>
      <origin rpy="0 0 0" xyz="0 0 0"/>
      <mass value="5"/>
      <inertia ixx="0.03517613092447916" ixy="0" ixz="0" iyy="0.06175012851562499" iyz="0" izz="0.03517613092447916"/>
    </inertial>
    <visual>
      <origin rpy="0 1.5707963267948966 1.5707963267948966" xyz="0 0 0"/>
      <geometry>
        <cylinder length="0.1016" radius="0.15716249999999998"/>
      </geometry>
    </visual>
    <collision>
      <origin rpy="0 1.5707963267948966 1.5707963267948966" xyz="0 0 0"/>
      <geometry>
        <cylinder length="0.1016" radius="0.15716249999999998"/>
      </geometry>
    </collision>
  </link>
  <joint name="right_wheel_joint" type="continuous">
    <origin rpy="0 0 0" xyz="0 -0.3937 0.04603749999999998"/>
    <parent link="base_link"/>
    <child link="right_wheel_link"/>
    <axis rpy="0 0 0" xyz="0 1 0"/>
    <limit effort="1000" velocity="1000"/>
    <dynamics damping="0.0001"/>
  </joint>
  <!-- Wheel color & physics-->
  <gazebo reference="right_wheel_link">
    <material>Gazebo/Green</material>
    <mu1 value="1.0"/>
    <mu2 value="1.0"/>
    <kp value="10000000.0"/>
    <kd value="1.0"/>
    <maxVel>1.0</maxVel>
    <minDepth>0.00</minDepth>
  </gazebo>
  <!-- Wheel link -->
  <link name="left_wheel_link">
    <inertial>
      <origin rpy="0 0 0" xyz="0 0 0"/>
      <mass value="5"/>
      <inertia ixx="0.03517613092447916" ixy="0" ixz="0" iyy="0.06175012851562499" iyz="0" izz="0.03517613092447916"/>
    </inertial>
    <visual>
      <origin rpy="0 1.5707963267948966 1.5707963267948966" xyz="0 0 0"/>
      <geometry>
        <cylinder length="0.1016" radius="0.15716249999999998"/>
      </geometry>
    </visual>
    <collision>
      <origin rpy="0 1.5707963267948966 1.5707963267948966" xyz="0 0 0"/>
      <geometry>
        <cylinder length="0.1016" radius="0.15716249999999998"/>
      </geometry>
    </collision>
  </link>
  <joint name="left_wheel_joint" type="continuous">
    <origin rpy="0 0 0" xyz="0 0.3937 0.04603749999999998"/>
    <parent link="base_link"/>
    <child link="left_wheel_link"/>
    <axis rpy="0 0 0" xyz="0 1 0"/>
    <limit effort="1000" velocity="1000"/>
    <dynamics damping="0.0001"/>
  </joint>
  <!-- Wheel color & physics-->
  <gazebo reference="left_wheel_link">
    <material>Gazebo/Green</material>
    <mu1 value="1.0"/>
    <mu2 value="1.0"/>
    <kp value="10000000.0"/>
    <kd value="1.0"/>
    <maxVel>1.0</maxVel>
    <minDepth>0.00</minDepth>
  </gazebo>
  <!-- Depth camera base link -->
  <link name="zed_base_link"/>
  <joint name="zed_base_joint" type="fixed">
    <origin rpy="0 0.1745327777 0" xyz="0.16939666399999997 0 0.7415796699999999"/>
    <parent link="base_link"/>
    <child link="zed_base_link"/>
    <axis xyz="0 1 0"/>
  </joint>
  <!-- Depth camera link -->
  <link name="zed_link">
    <inertial>
      <origin rpy="0 0 0" xyz="0 0 0"/>
      <mass value="0.23"/>
      <inertia ixx="0.0006061961458333333" ixy="0.0" ixz="0.0" iyy="5.314288958333334e-05" iyz="0.0" izz="0.0006242616395833333"/>
    </inertial>
    <visual>
      <origin rpy="0 0 0" xyz="0 0 0"/>
      <geometry>
        <box size="0.0431 0.17525 0.03025"/>
      </geometry>
    </visual>
    <collision>
      <origin rpy="0 0 0" xyz="0 0 0"/>
      <geometry>
        <box size="0.0431 0.17525 0.03025"/>
      </geometry>
    </collision>
  </link>
  <joint name="zed_joint" type="fixed">
    <origin rpy="0 0 0" xyz="0 0 0.015125"/>
    <parent link="zed_base_link"/>
    <child link="zed_link"/>
  </joint>
  <!-- Depth camera optical link -->
  <link name="zed_optical_link"/>
  <joint name="zed_optical_joint" type="fixed">
    <origin rpy="-1.5707963267948966 0 -1.5707963267948966" xyz="0 0 0"/>
    <parent link="zed_link"/>
    <child link="zed_optical_link"/>
  </joint>
  <!-- Depth camera color -->
  <gazebo reference="zed_link">
    <material>Gazebo/Black</material>
  </gazebo>
  <!-- Depth camera plugin -->
  <gazebo reference="zed_link">
    <sensor name="zed" type="depth">
      <update_rate>15.0</update_rate>
      <visualize>true</visualize>
      <always_on>true</always_on>
      <camera>
        <horizontal_fov>1.91986</horizontal_fov>
        <image>
          <width>2560</width>
          <height>720</height>
          <format>B8G8R8</format>
        </image>
        <clip>
          <near>0.3</near>
          <far>20</far>
        </clip>
      </camera>
      <plugin filename="libgazebo_ros_camera.so" name="zed_controller">
        <frame_name>zed_optical_link</frame_name>
        <min_depth>0</min_depth>
        <max_depth>100</max_depth>
      </plugin>
    </sensor>
  </gazebo>
  <joint name="velodyne_base_mount_joint" type="fixed">
    <origin rpy="0 0 0" xyz="0 0 0.8267699999999999"/>
    <parent link="base_link"/>
    <child link="velodyne_base_link"/>
  </joint>
  <link name="velodyne_base_link">
    <inertial>
      <mass value="0.83"/>
      <origin xyz="0 0 0.03585"/>
      <inertia ixx="0.000908059425" ixy="0" ixz="0" iyy="0.000908059425" iyz="0" izz="0.0011049624"/>
    </inertial>
    <visual>
      <geometry>
        <mesh filename="file:///home/umarv/ws/install/velodyne_description/share/velodyne_description/meshes/VLP16_base_1.dae"/>
      </geometry>
    </visual>
    <visual>
      <geometry>
        <mesh filename="file:///home/umarv/ws/install/velodyne_description/share/velodyne_description/meshes/VLP16_base_2.dae"/>
      </geometry>
    </visual>
    <collision>
      <origin rpy="0 0 0" xyz="0 0 0.03585"/>
      <geometry>
        <cylinder length="0.0717" radius="0.0516"/>
      </geometry>
    </collision>
  </link>
  <joint name="velodyne_base_scan_joint" type="fixed">
    <origin rpy="0 0 0" xyz="0 0 0.0377"/>
    <parent link="velodyne_base_link"/>
    <child link="velodyne"/>
  </joint>
  <link name="velodyne">
    <inertial>
      <mass value="0.01"/>
      <origin xyz="0 0 0"/>
      <inertia ixx="1e-7" ixy="0" ixz="0" iyy="1e-7" iyz="0" izz="1e-7"/>
    </inertial>
    <visual>
      <origin xyz="0 0 -0.0377"/>
      <geometry>
        <mesh filename="file:///home/umarv/ws/install/velodyne_description/share/velodyne_description/meshes/VLP16_scan.dae"/>
      </geometry>
    </visual>
  </link>
  <!-- Gazebo requires the velodyne_gazebo_plugins package -->
  <gazebo reference="velodyne">
    <sensor name="velodyne-VLP16" type="gpu_ray">
      <pose>0 0 0 0 0 0</pose>
      <visualize>false</visualize>
      <update_rate>20</update_rate>
      <ray>
        <scan>
          <horizontal>
            <samples>440</samples>
            <resolution>1</resolution>
            <min_angle>-3.141592653589793</min_angle>
            <max_angle>3.141592653589793</max_angle>
          </horizontal>
          <vertical>
            <samples>16</samples>
            <resolution>1</resolution>
            <min_angle>-0.2617993877991494</min_angle>
            <max_angle>
                  0.2617993877991494</max_angle>
          </vertical>
        </scan>
        <range>
          <min>0.3</min>
          <max>131.0</max>
          <resolution>0.001</resolution>
        </range>
        <noise>
          <type>gaussian</type>
          <mean>0.0</mean>
          <stddev>0.0</stddev>
        </noise>
      </ray>
      <plugin filename="libgazebo_ros_velodyne_laser.so" name="gazebo_ros_laser_controller">
        <topicName>/velodyne_points</topicName>
        <frameName>velodyne</frameName>
        <min_range>0.9</min_range>
        <max_range>130.0</max_range>
        <gaussianNoise>0.008</gaussianNoise>
      </plugin>
    </sensor>
  </gazebo>
  <!-- Imu base link -->
  <link name="imu_base_link"/>
  <joint name="imu_base_joint" type="fixed">
    <origin rpy="0 0 0" xyz="-0.29527499999999995 0 0.5588"/>
    <parent link="base_link"/>
    <child link="imu_base_link"/>
    <axis xyz="0 1 0"/>
  </joint>
  <!-- Imu link -->
  <link name="imu_link">
    <inertial>
      <origin rpy="0 0 0" xyz="0 0 0"/>
      <mass value="0.025"/>
      <inertia ixx="2.0833333333333334e-06" ixy="0.0" ixz="0.0" iyy="5.416666666666668e-06" iyz="0.0" izz="7.083333333333334e-06"/>
    </inertial>
    <visual>
      <origin rpy="0 0 0" xyz="0 0 0"/>
      <geometry>
        <box size="0.05 0.03 0.01"/>
      </geometry>
    </visual>
    <collision>
      <origin rpy="0 0 0" xyz="0 0 0"/>
      <geometry>
        <box size="0.05 0.03 0.01"/>
      </geometry>
    </collision>
  </link>
  <joint name="imu_joint" type="fixed">
    <origin rpy="0 0 0" xyz="0 0 0.005"/>
    <parent link="imu_base_link"/>
    <child link="imu_link"/>
  </joint>
  <!-- Imu color -->
  <gazebo reference="imu_link">
    <material>Gazebo/Purple</material>
  </gazebo>
  <!-- Imu plugin -->
  <gazebo reference="imu_link">
    <gravity>true</gravity>
    <sensor name="imu" type="imu">
      <always_on>true</always_on>
      <update_rate>100.0</update_rate>
      <visualize>true</visualize>
      <topic>__default_topic__</topic>
      <pose>0 0 0 0 0 0</pose>
      <plugin filename="libgazebo_ros_imu_sensor.so" name="imu_controller">
        <topicName>imu</topicName>
        <bodyName>imu_link</bodyName>
        <updateRateHZ>100.0</updateRateHZ>
        <gaussianNoise>0.0</gaussianNoise>
        <xyzOffset>0 0 0</xyzOffset>
        <rpyOffset>0 0 0</rpyOffset>
        <frameName>imu_link</frameName>
        <initialOrientationAsReference>false</initialOrientationAsReference>
      </plugin>
    </sensor>
  </gazebo>
  <!-- Encoder -->
  <link name="encoder"/>
  <joint name="encoder_joint" type="fixed">
    <origin rpy="0 0 0" xyz="0 0 0.04603749999999998"/>
    <parent link="base_link"/>
    <child link="encoder"/>
    <axis xyz="0 1 0"/>
  </joint>
  <gazebo>
    <plugin filename="libgazebo_ros_diff_drive.so" name="differential_drive_controller">
      <update_rate>100.0</update_rate>
      <robot_base_frame>base_link</robot_base_frame>
      <command_topic>cmd_vel</command_topic>
      <left_joint>left_wheel_joint</left_joint>
      <right_joint>right_wheel_joint</right_joint>
      <wheel_separation>0.7874</wheel_separation>
      <wheel_diameter>0.31432499999999997</wheel_diameter>
      <publish_tf>true</publish_tf>
      <publish_wheel_tf>true</publish_wheel_tf>
      <max_wheel_acceleration>1.8</max_wheel_acceleration>
      <max_wheel_torque>30</max_wheel_torque>
      <odometrySource>encoder</odometrySource>
      <odometry_topic>odom</odometry_topic>
      <odometry_frame>odom</odometry_frame>
      <publish_odom>true</publish_odom>
      <publish_odom_tf>true</publish_odom_tf>
      <legacy_mode>false</legacy_mode>
      <ros_debug_level>na</ros_debug_level>
    </plugin>
  </gazebo>
</robot>
